Workbook
Name _Column: Table7[[#All],[Region]]
Name _ColumnB: Table9[[#All],[Region]]
Name _Start: Table7[[#Headers],[Country]]
Name _StartB: Table9[[#Headers],[NS name]]
Name Comment: Comments!$B$4
Name Country: Table6[Country]
Name Data_branches: Start!$O$29
Name Data_Country: Start!$K$12
Name Data_EA1: Start!$E$18
Name Data_EA2: Start!$L$18
Name Data_EA3: Start!$E$24
Name Data_MDR1: Start!$E$16
Name Data_MDR2: Start!$L$16
Name Data_MDR3: Start!$E$22
Name Data_staff: Start!$F$29
Name Data_units: Start!$L$29
Name Data_vol: Start!$C$29
Name Language: Start!$M$2
Name NS: Table1[NS]
Name Reach_EA1: 'People to be reached'!$G$11
Name Reach_EA2: 'People to be reached'!$G$12
Name Reach_EA3: 'People to be reached'!$G$13
Name Region: Table8[Region]
Name RegionAR: Table8[RegionAR]
Name RegionFR: Table8[RegionFR]
Name RegionSP: Table8[RegionSP]
Name TR: _xlfn.LAMBDA(_xlpm.id, INDEX(Translations[], MATCH(_xlpm.id, Translations[id], 0), _xlfn.XMATCH(Language, Translations[#Headers]) ) )
Name Version: TemplateData!$I$11

Sheet TemplateData
A1: Country | B1: NS | C1: FR | D1: SP | E1: AR | G1: Country | I1: Region | J1: RegionFR | K1: RegionSP | L1: RegionAR | N1: Region | O1: Country | Q1: Region | R1: NS name | S1: Value | U1: ISO3 | V1: Country | W1: Indicator | X1: ValueNum | Y1: Round | AA1: Country | AB1: Attribute | AC1: Value | AD1: Year | AF1: id | AG1: EN | AH1: FR | AI1: SP | AJ1: AR
A2: Afghanistan | B2: Afghan Red Crescent | C2: Croissant-Rouge afghan | D2: Media Luna Roja Afgana | E2: الهلال الأحمر الأفغاني | G2: Afghanistan | I2: Asia Pacific | J2: Asie-Pacifique | K2: Asia Pacífico | L2: آسيا والمحيط الهادئ | N2: Africa | O2: Angola | Q2: Africa | R2: Angola Red Cross | S2: Angola Red Cross | U2: AFG | V2: Afghanistan | W2: Number of National Society Local Units | X2: 329 | Y2: AR25 | AA2: Afghanistan | AB2: Branches | AC2: 34 | AD2: 2024 | AF2: SP2 | AG2: Response - Disasters and Crises | AH2: Réponse - Catastrophes et crises | AI2: Respuesta - Desastres y crisis | AJ2: الاستجابة - الكوارث والأزمات
A3: Albania | B3: Albanian Red Cross | C3: Croix-Rouge albanaise | D3: Cruz Roja de Albania | E3: الصليب الأحمر الألباني | G3: Albania | I3: Africa | J3: Afrique | K3: África | L3: أفريقيا | N3: Africa | O3: Benin | Q3: Africa | R3: Baphalali Eswatini Red Cross Society | S3: Baphalali Eswatini Red Cross Society | U3: AFG | V3: Afghanistan | W3: Number of National Society branches | X3: 34 | Y3: AR25 | AA3: Afghanistan | AB3: Local Units | AC3: 329 | AD3: 2024 | AF3: SP1 | AG3: Resilience - Climate and Environment | AH3: Résilience - Climat et environnement | AI3: Resiliencia - Clima y medio ambiente | AJ3: الصمود - المناخ والبيئة
A4: Algeria | B4: Algerian Red Crescent | C4: Croissant-Rouge algérien | D4: Media Luna Roja Argelina | E4: الهلال الأحمر الجزائري | G4: Algeria | I4: Americas | J4: Amériques | K4: Américas | L4: الأمريكتان | N4: Africa | O4: Botswana | Q4: Africa | R4: Botswana Red Cross Society | S4: Botswana Red Cross Society | U4: AFG | V4: Afghanistan | W4: Number of paid staff | X4: 4006 | Y4: AR25 | AA4: Afghanistan | AB4: Staff | AC4: 5’000 | AD4: 2024 | AF4: SP3 | AG4: Resilience - Health and Well-being | AH4: Résilience - Santé et bien-être | AI4: Resiliencia - Salud y bienestar | AJ4: الصمود - الصحة والرفاه
A5: United States | B5: American Red Cross | C5: Croix-Rouge américaine | D5: Cruz Roja Americana | E5: الصليب الأحمر الأمريكي | G5: Andorra | I5: Europe and Central Asia | J5: Europe et Asie centrale | K5: Europa y Asia Central | L5: أوروبا وآسيا الوسطى | N5: Africa | O5: Burkina Faso | Q5: Africa | R5: Burkinabe Red Cross Society | S5: Burkinabe Red Cross Society | U5: AFG | V5: Afghanistan | W5: Number of people volunteering | X5: 26568 | Y5: AR25 | AA5: Afghanistan | AB5: Volunteers | AC5: 30’000 | AD5: 2024 | AF5: SP4 | AG5: Resilience - Migration and Displacement | AH5: Résilience - Migration et déplacements | AI5: Resiliencia - Migración y desplazamiento | AJ5: الصمود - الهجرة والنزوح
A6: Andorra | B6: Andorran Red Cross | C6: Croix-Rouge andorrane | D6: Cruz Roja Andorrana | E6: الصليب الأحمر الأندوري | G6: Angola | I6: Middle East and North Africa | J6: Moyen-Orient et Afrique du Nord | K6: Medio Oriente y Norte de África | L6: الشرق الأوسط وشمال أفريقيا | N6: Africa | O6: Burundi | Q6: Africa | R6: Burundi Red Cross | S6: Burundi Red Cross | U6: ALB | V6: Albania | W6: Number of National Society Local Units | X6: 39 | Y6: AR25 | AA6: Albania | AB6: Branches | AC6: 39 | AD6: 2024 | AF6: SP5 | AG6: Respect - Values, Power and Inclusion | AH6: Respect - Valeurs, pouvoir et inclusion | AI6: Respeto - Valores, poder e inclusión | AJ6: الاحترام - القيم والسلطة والشمول
A7: Angola | B7: Angola Red Cross | C7: Croix-Rouge angolaise | D7: Cruz Roja de Angola | E7: الصليب الأحمر الأنغولي | G7: Antigua and Barbuda | N7: Africa | O7: Cameroon | Q7: Africa | R7: Cameroon Red Cross Society | S7: Cameroon Red Cross Society | U7: ALB | V7: Albania | W7: Number of National Society branches | X7: 39 | Y7: AR25 | AA7: Albania | AB7: Local Units | AC7: 39 | AD7: 2024 | AF7: Efs | AG7: Enabling Functions | AH7: Fonctions habilitantes | AI7: Funciones habilitantes | AJ7: الوظائف التمكينية
A8: Antigua and Barbuda | B8: Antigua and Barbuda Red Cross | C8: Croix-Rouge d'Antigua-et-Barbuda | D8: Cruz Roja de Antigua y Barbuda | E8: الصليب الأحمر لأنتيغوا وباربودا | G8: Argentina | N8: Africa | O8: Cape Verde | Q8: Africa | R8: Central African Red Cross Society | S8: Central African Red Cross Society | U8: ALB | V8: Albania | W8: Number of paid staff | X8: 58 | Y8: AR25 | AA8: Albania | AB8: Staff | AC8: 58 | AD8: 2024 | AF8: T01 | AG8: 2027 Planning - Start here | AH8: Planification 2026 - Commencez ici | AI8: Planificación 2027 - Comience aquí | AJ8: تخطيط 2027 - ابدأ هنا
A9: Argentina | B9: Argentine Red Cross | C9: Croix-Rouge argentine | D9: Cruz Roja Argentina | E9: الصليب الأحمر الأرجنتيني | G9: Armenia | N9: Africa | O9: Central African Republic | Q9: Africa | R9: Congolese Red Cross | S9: Congolese Red Cross | U9: ALB | V9: Albania | W9: Number of people volunteering | X9: 2800 | Y9: AR25 | AA9: Albania | AB9: Volunteers | AC9: 3’000 | AD9: 2024 | AF9: T02 | AG9: Language | AH9: Langue | AI9: Idioma | AJ9: اللغة
A10: Armenia | B10: Armenian Red Cross Society | C10: Société de la Croix-Rouge arménienne | D10: Sociedad de la Cruz Roja de Armenia | E10: جمعية الصليب الأحمر الأرمني | G10: Australia | N10: Africa | O10: Chad | Q10: Africa | R10: Ethiopian Red Cross Society | S10: Ethiopian Red Cross Society | U10: DZA | V10: Algeria | W10: Number of National Society Local Units | X10: 592 | Y10: AR25 | AA10: Algeria | AB10: Branches | AC10: 58 | AD10: 2024 | AF10: T03 | AG10: Instructions | AH10: Instructions | AI10: Instrucciones | AJ10: تعليمات
A11: Australia | B11: Australian Red Cross | C11: Croix-Rouge australienne | D11: Cruz Roja Australiana | E11: الصليب الأحمر الأسترالي | G11: Austria | I11: P27.V1.1 | N11: Africa | O11: Comoros | Q11: Africa | R11: Gabonese Red Cross Society | S11: Gabonese Red Cross Society | U11: DZA | V11: Algeria | W11: Number of National Society branches | X11: 58 | Y11: AR25 | AA11: Algeria | AB11: Local Units | AC11: 592 | AD11: 2024 | AF11: T04 | AG11: Cell open for input | AH11: Cellule ouverte pour saisie | AI11: Celda abierta para entrada | AJ11: الخلية مفتوحة للإدخال
A12: Austria | B12: Austrian Red Cross | C12: Croix-Rouge autrichienne | D12: Cruz Roja Austríaca | E12: الصليب الأحمر النمساوي | G12: Azerbaijan | N12: Africa | O12: Congo | Q12: Africa | R12: Ghana Red Cross Society | S12: Ghana Red Cross Society | U12: DZA | V12: Algeria | W12: Number of paid staff | X12: 181 | Y12: AR25 | AA12: Algeria | AB12: Staff | AC12: 181 | AD12: 2024 | AF12: T05 | AG12: Cell Locked (or Automatically prefilled) | AH12: Cellule verrouillée ou préremplie automatiquement | AI12: Celda bloqueada (o rellenada automáticamente) | AJ12: الخلية مقفلة أو معبئة مسبقاً
A13: Bahrain | B13: Bahrain Red Crescent Society | C13: Société du Croissant-Rouge de Bahreïn | D13: Sociedad de la Media Luna Roja de Bahrein | E13: جمعية الهلال الأحمر البحريني | G13: Bahamas | N13: Africa | O13: Congo, the Democratic Republic of the | Q13: Africa | R13: Kenya Red Cross Society | S13: Kenya Red Cross Society | U13: DZA | V13: Algeria | W13: Number of people volunteering | X13: 36000 | Y13: AR25 | AA13: Algeria | AB13: Volunteers | AC13: 36’000 | AD13: 2024 | AF13: T06 | AG13: Guidance | AH13: Guidage | AI13: Guía | AJ13: إرشادات
A14: Bangladesh | B14: Bangladesh Red Crescent Society | C14: Croissant-Rouge du Bangladesh | D14: Media Luna Roja de Bangladesh | E14: جمعية الهلال الأحمر البنغلاديشي | G14: Bahrain | N14: Africa | O14: Côte d'Ivoire | Q14: Africa | R14: Lesotho Red Cross Society | S14: Lesotho Red Cross Society | U14: AGO | V14: Angola | W14: Number of National Society Local Units | Y14: AR25 | AA14: Andorra | AB14: Branches | AC14: 1 | AD14: 2024 | AF14: T07 | AG14: Select your country | AH14: Sélectionnez votre pays | AI14: Seleccione su país | AJ14: اختر بلدك
A15: Eswatini, the Kingdom of | B15: Baphalali Eswatini Red Cross Society | C15: Croix-Rouge d'Eswatini | D15: Cruz Roja de Suazilandia | E15: جمعية الصليب الأحمر بفالاتشي إسواتيني | G15: Bangladesh | N15: Africa | O15: Djibouti | Q15: Africa | R15: Liberian Red Cross Society | S15: Liberian Red Cross Society | U15: AGO | V15: Angola | W15: Number of National Society branches | Y15: AR25 | AA15: Andorra | AB15: Local Units | AC15: 1 | AD15: 2024 | AF15: T08 | AG15: Region | AH15: Région | AI15: Región | AJ15: المنطقة
A16: Belarus | B16: Belarus Red Cross | C16: Croix-Rouge du Bélarus | D16: Cruz Roja de Belarús | E16: الصليب الأحمر البيلاروسي | G16: Barbados | N16: Africa | O16: Equatorial Guinea | Q16: Africa | R16: Malagasy Red Cross Society | S16: Malagasy Red Cross Society | U16: AGO | V16: Angola | W16: Number of paid staff | Y16: AR25 | AA16: Andorra | AB16: Staff | AC16: 76 | AD16: 2024 | AF16: T09 | AG16: Country | AH16: Pays | AI16: País | AJ16: البلد
A17: Belgium | B17: Belgian Red Cross | C17: Croix-Rouge de Belgique | D17: Cruz Roja de Bélgica | E17: الصليب الأحمر البلجيكي | G17: Belarus | N17: Africa | O17: Eswatini, the Kingdom of | Q17: Africa | R17: Malawi Red Cross Society | S17: Malawi Red Cross Society | U17: AGO | V17: Angola | W17: Number of people volunteering | Y17: AR25 | AA17: Andorra | AB17: Volunteers | AC17: 413 | AD17: 2024 | AF17: T10 | AG17: Emergency Appeal 1 | AH17: Appel d'Urgence 1 | AI17: Llamamiento de Emergencia 1 | AJ17: النداء الطارئ 1
A18: Belize | B18: Belize Red Cross Society | C18: Société de la Croix-Rouge du Belize | D18: Sociedad de la Cruz Roja de Belice | E18: جمعية الصليب الأحمر في بليز | G18: Belgium | N18: Africa | O18: Ethiopia | Q18: Africa | R18: Mali Red Cross | S18: Mali Red Cross | U18: ATG | V18: Antigua and Barbuda | W18: Number of National Society Local Units | X18: 1 | Y18: AR25 | AA18: Angola | AB18: Branches | AC18: 18 | AD18: 2024 | AF18: T11 | AG18: Emergency Appeal 2 | AH18: Appel d'Urgence 2 | AI18: Llamamiento de Emergencia 2 | AJ18: النداء الطارئ 2
A19: Bhutan | B19: Bhutan Red Cross | C19: Croix-Rouge du Bhoutan | D19: Cruz Roja de Bután | E19: الصليب الأحمر البوتاني | G19: Belize | N19: Africa | O19: Gabon | Q19: Africa | R19: Mauritanian Red Crescent | S19: Mauritanian Red Crescent | U19: ATG | V19: Antigua and Barbuda | W19: Number of National Society branches | X19: 0 | Y19: AR25 | AA19: Angola | AB19: Local Units | AC19: 19 | AD19: 2024 | AF19: T12 | AG19: MDR code | AH19: Code MDR | AI19: Código MDR | AJ19: رمز MDR
A20: Bolivia, Plurinational State of | B20: Bolivian Red Cross | C20: Croix-Rouge bolivienne | D20: Cruz Roja Boliviana | E20: الصليب الأحمر البوليفي | G20: Benin | N20: Africa | O20: Gambia | Q20: Africa | R20: Mauritius Red Cross Society | S20: Mauritius Red Cross Society | U20: ATG | V20: Antigua and Barbuda | W20: Number of paid staff | X20: 5 | Y20: AR25 | AA20: Angola | AB20: Staff | AC20: 77 | AD20: 2024 | AF20: T13 | AG20: Name | AH20: Nom | AI20: Nombre | AJ20: الاسم
A21: Botswana | B21: Botswana Red Cross Society | C21: Société de la Croix-Rouge du Botswana | D21: Sociedad de la Cruz Roja de Botsuana | E21: جمعية الصليب الأحمر البوتسواني | G21: Bhutan | N21: Africa | O21: Ghana | Q21: Africa | R21: Mozambique Red Cross Society | S21: Mozambique Red Cross Society | U21: ATG | V21: Antigua and Barbuda | W21: Number of people volunteering | X21: 66 | Y21: AR25 | AA21: Angola | AB21: Volunteers | AC21: 5’000 | AD21: 2024 | AF21: T14 | AG21: Emergency Appeal 3 | AH21: Appel d'Urgence 3 | AI21: Llamamiento de Emergencia 3 | AJ21: النداء الطارئ 3
A22: Brazil | B22: Brazilian Red Cross | C22: Croix-Rouge brésilienne | D22: Cruz Roja Brasileña | E22: الصليب الأحمر البرازيلي | G22: Bolivia, Plurinational State of | N22: Africa | O22: Guinea | Q22: Africa | R22: Namibia Red Cross | S22: Namibia Red Cross | U22: ARG | V22: Argentina | W22: Number of National Society Local Units | X22: 65 | Y22: AR25 | AA22: Antigua and Barbuda | AB22: Local Units | AC22: 1 | AD22: 2024 | AF22: T15 | AG22: National Society key figures | AH22: Chiffres clés de la Société nationale | AI22: Cifras clave de la Sociedad Nacional | AJ22: الأرقام الرئيسية للجمعية الوطنية
A23: United Kingdom | B23: British Red Cross | C23: Croix-Rouge britannique | D23: Cruz Roja Británica | E23: الصليب الأحمر البريطاني | G23: Bosnia and Herzegovina | N23: Africa | O23: Guinea-Bissau | Q23: Africa | R23: Nigerian Red Cross Society | S23: Nigerian Red Cross Society | U23: ARG | V23: Argentina | W23: Number of National Society branches | X23: 63 | Y23: AR25 | AA23: Antigua and Barbuda | AB23: Staff | AC23: 5 | AD23: 2024 | AF23: T16 | AG23: Volunteers | AH23: Volontaires | AI23: Voluntarios | AJ23: المتطوعون
A24: Brunei Darussalam | B24: Brunei Darussalam Red Crescent Society | C24: Croissant-Rouge de Brunéi | D24: Media Luna Roja de Brunei | E24: جمعية الهلال الأحمر في بروناي دار السلام | G24: Botswana | N24: Africa | O24: Kenya | Q24: Africa | R24: Red Crescent Society of Djibouti | S24: Red Crescent Society of Djibouti | U24: ARG | V24: Argentina | W24: Number of paid staff | X24: 1855 | Y24: AR25 | AA24: Antigua and Barbuda | AB24: Volunteers | AC24: 66 | AD24: 2024 | AF24: T17 | AG24: Staff | AH24: Personnel | AI24: Personal | AJ24: الموظفون
A25: Bulgaria | B25: Bulgarian Red Cross | C25: Croix-Rouge bulgare | D25: Cruz Roja Búlgara | E25: الصليب الأحمر البلغاري | G25: Brazil | N25: Africa | O25: Lesotho | Q25: Africa | R25: Red Cross Society of Côte d'Ivoire | S25: Red Cross Society of Côte d'Ivoire | U25: ARG | V25: Argentina | W25: Number of people volunteering | X25: 7160 | Y25: AR25 | AA25: Argentina | AB25: Branches | AC25: 63 | AD25: 2024 | AF25: T18 | AG25: Local Units | AH25: Unités locales | AI25: Unidades locales | AJ25: الوحدات المحلية
A26: Burkina Faso | B26: Burkinabe Red Cross Society | C26: Croix-Rouge burkinabè | D26: Cruz Roja de Burkina Faso | E26: جمعية الصليب الأحمر البوركينية | G26: Brunei Darussalam | N26: Africa | O26: Liberia | Q26: Africa | R26: Red Cross Society of Guinea | S26: Red Cross Society of Guinea | U26: ARM | V26: Armenia | W26: Number of National Society Local Units | X26: 54 | Y26: AR25 | AA26: Argentina | AB26: Local Units | AC26: 65 | AD26: 2024 | AF26: T19 | AG26: Branches | AH26: Branches | AI26: Sucursales | AJ26: الفروع
A27: Burundi | B27: Burundi Red Cross | C27: Croix-Rouge du Burundi | D27: Cruz Roja de Burundi | E27: الصليب الأحمر البوروندي | G27: Bulgaria | N27: Africa | O27: Madagascar | Q27: Africa | R27: Red Cross Society of Guinea-Bissau | S27: Red Cross Society of Guinea-Bissau | U27: ARM | V27: Armenia | W27: Number of National Society branches | X27: 12 | Y27: AR25 | AA27: Argentina | AB27: Staff | AC27: 2’000 | AD27: 2024 | AF27: T20 | AG27: People to be reached by | AH27: Personnes à atteindre par | AI27: Personas a ser alcanzadas por | AJ27: الأشخاص المستهدفون بواسطة
A28: Cambodia | B28: Cambodian Red Cross Society | C28: Croix-Rouge cambodgienne | D28: Cruz Roja de Camboya | E28: جمعية الصليب الأحمر الكمبودي | G28: Burkina Faso | N28: Africa | O28: Malawi | Q28: Africa | R28: Red Cross Society of Niger | S28: Red Cross Society of Niger | U28: ARM | V28: Armenia | W28: Number of paid staff | X28: 300 | Y28: AR25 | AA28: Argentina | AB28: Volunteers | AC28: 7’000 | AD28: 2024 | AF28: T21 | AG28: Longer term programmes | AH28: Programmes à plus long terme | AI28: Programas a más largo plazo | AJ28: برامج طويلة الأجل
A29: Cameroon | B29: Cameroon Red Cross Society | C29: Croix-Rouge camerounaise | D29: Cruz Roja del Camerún | E29: جمعية الصليب الأحمر الكاميروني | G29: Burundi | N29: Africa | O29: Mali | Q29: Africa | R29: Red Cross of Benin | S29: Red Cross of Benin | U29: ARM | V29: Armenia | W29: Number of people volunteering | X29: 1792 | Y29: AR25 | AA29: Armenia | AB29: Branches | AC29: 12 | AD29: 2024 | AF29: T22 | AG29: Year | AH29: Année | AI29: Año | AJ29: السنة
... A52: Ghana | B52: Ghana Red Cross Society | C52: Croix-Rouge du Ghana | D52: Cruz Roja de Ghana | E52: جمعية الصليب الأحمر الغاني | G52: Dominican Republic | N52: Americas | O52: Bahamas | Q52: Afrique | R52: Croissant-Rouge mauritanien | S52: Mauritanian Red Crescent | U52: BEN | V52: Benin | W52: Number of paid staff | X52: 85 | Y52: AR25 | AA52: Bahrain | AB52: Volunteers | AC52: 49 | AD52: 2024 | AF52: T55 | AG52: USE THIS TEMPLATE ONLY IF YOU HAVE CONNECTIVITY ISSUES AND CAN'T ACCESS THE | AH52: UTILISEZ CE MODÈLE UNIQUEMENT SI VOUS RENCONTREZ DES PROBLÈMES DE CONNEXION ET NE POUVEZ PAS ACCÉDER AU | AI52: UTILICE ESTA PLANTILLA ÚNICAMENTE SI TIENE PROBLEMAS DE CONECTIVIDAD Y NO PUEDE ACCEDER AL | AJ52: استخدم هذا النموذج فقط إذا كنت تواجه مشكلات في الاتصال ولا يمكنك الوصول إلى
A53: Grenada | B53: Grenada Red Cross Society | C53: Croix-Rouge de Grenade | D53: Cruz Roja de Granada | E53: جمعية الصليب الأحمر في غرينادا | G53: Ecuador | N53: Americas | O53: Barbados | Q53: Afrique | R53: Croissant-Rouge soudanais | S53: The Sudanese Red Crescent | U53: BEN | V53: Benin | W53: Number of people volunteering | X53: 12600 | Y53: AR25 | AA53: Bangladesh | AB53: Branches | AC53: 68 | AD53: 2024
A54: Guatemala | B54: Guatemalan Red Cross | C54: Croix-Rouge du Guatemala | D54: Cruz Roja Guatemalteca | E54: الصليب الأحمر الغواتيمالي | G54: Egypt | N54: Americas | O54: Belize | Q54: Afrique | R54: Croix-Rouge angolaise | S54: Angola Red Cross | U54: BIH | V54: Bosnia and Herzegovina | W54: Number of National Society Local Units | X54: 165 | Y54: AR25 | AA54: Bangladesh | AB54: Local Units | AC54: 155 | AD54: 2024
A55: Haiti | B55: Haiti Red Cross Society | C55: Croix-Rouge haïtienne | D55: Sociedad de la Cruz Roja de Haití | E55: جمعية الصليب الأحمر الهايتي | G55: El Salvador | N55: Americas | O55: Bolivia, Plurinational State of | Q55: Afrique | R55: Croix-Rouge burkinabè | S55: Burkinabe Red Cross Society | U55: BIH | V55: Bosnia and Herzegovina | W55: Number of National Society branches | X55: 21 | Y55: AR25 | AA55: Bangladesh | AB55: Staff | AC55: 3’000 | AD55: 2024
A56: Greece | B56: Hellenic Red Cross | C56: Croix-Rouge hellénique | D56: Cruz Roja Helénica | E56: الصليب الأحمر اليوناني | G56: Equatorial Guinea | N56: Americas | O56: Brazil | Q56: Afrique | R56: Croix-Rouge béninoise | S56: Red Cross of Benin | U56: BIH | V56: Bosnia and Herzegovina | W56: Number of paid staff | X56: 339 | Y56: AR25 | AA56: Bangladesh | AB56: Volunteers | AC56: 132’000 | AD56: 2024
A57: Honduras | B57: Honduran Red Cross | C57: Croix-Rouge du Honduras | D57: Cruz Roja Hondureña | E57: الصليب الأحمر الهندوراسي | G57: Estonia | N57: Americas | O57: Canada | Q57: Afrique | R57: Croix-Rouge camerounaise | S57: Cameroon Red Cross Society | U57: BIH | V57: Bosnia and Herzegovina | W57: Number of people volunteering | X57: 9781 | Y57: AR25 | AA57: Barbados | AB57: Local Units | AC57: 1 | AD57: 2024
A58: Hungary | B58: Hungarian Red Cross | C58: Croix-Rouge hongroise | D58: Cruz Roja Húngara | E58: الصليب الأحمر المجري | G58: Eswatini, the Kingdom of | N58: Americas | O58: Chile | Q58: Afrique | R58: Croix-Rouge congolaise | S58: Congolese Red Cross | U58: BWA | V58: Botswana | W58: Number of National Society Local Units | Y58: AR25 | AA58: Barbados | AB58: Staff | AC58: 7 | AD58: 2024
A59: Iceland | B59: Icelandic Red Cross | C59: Croix-Rouge islandaise | D59: Cruz Roja Islandesa | E59: الصليب الأحمر الأيسلندي | G59: Ethiopia | N59: Americas | O59: Colombia | Q59: Afrique | R59: Croix-Rouge d'Eswatini | S59: Baphalali Eswatini Red Cross Society | U59: BWA | V59: Botswana | W59: Number of National Society branches | Y59: AR25 | AA59: Barbados | AB59: Volunteers | AC59: 65 | AD59: 2024
A60: India | B60: Indian Red Cross Society | C60: Croix-Rouge de l'Inde | D60: Cruz Roja de la India | E60: جمعية الصليب الأحمر الهندي | G60: Fiji | N60: Americas | O60: Costa Rica | Q60: Afrique | R60: Croix-Rouge de Côte d'Ivoire | S60: Red Cross Society of Côte d'Ivoire | U60: BWA | V60: Botswana | W60: Number of paid staff | Y60: AR25 | AA60: Belgium | AB60: Branches | AC60: 364 | AD60: 2024
A61: Indonesia | B61: Indonesian Red Cross Society | C61: Croix-Rouge indonésienne | D61: Cruz Roja Indonesia | E61: جمعية الصليب الأحمر الإندونيسي | G61: Finland | N61: Americas | O61: Cuba | Q61: Afrique | R61: Croix-Rouge de Guinée équatoriale | S61: Red Cross of Equatorial Guinea | U61: BWA | V61: Botswana | W61: Number of people volunteering | Y61: AR25 | AA61: Belgium | AB61: Local Units | AC61: 364 | AD61: 2024
A62: Iraq | B62: Iraqi Red Crescent Society | C62: Croissant-Rouge de l'Iraq | D62: Media Luna Roja del Iraq | E62: جمعية الهلال الأحمر العراقي | G62: France | N62: Americas | O62: Dominica | Q62: Afrique | R62: Croix-Rouge de Maurice | S62: Mauritius Red Cross Society | U62: BRA | V62: Brazil | W62: Number of National Society Local Units | X62: 69 | Y62: AR25 | AA62: Belgium | AB62: Staff | AC62: 4’000 | AD62: 2024
...

Sheet Start
C2: =TR("T01") -> 2027 Planning - Start here | L2: =TR("T02") -> Language | M2: EN
B4: =TR("T03") -> Instructions
D6: {=TR("T04")} -> Cell open for input | G6: {=TR("T05")} -> Cell Locked (or Automatically prefilled) | N6: {=TR("T06")} -> Guidance
C8: {=TR("T55")} -> USE THIS TEMPLATE ONLY IF YOU HAVE CONNECTIVITY ISSUES AND CAN'T ACCESS THE | M8: DATABANK
B10: =TR("T07") -> Select your country
M11: {=IF(Data_Country="",TR("T44"),"")} -> ⮟ Select here first!
B12: =TR("T08") -> Region | G12: =TR("T09") -> Country
C15: {=TR("T10")} -> Emergency Appeal 1 | J15: {=TR("T11")} -> Emergency Appeal 2
D16: =TR("T12") -> MDR code | K16: =TR("T12") -> MDR code
D18: =TR("T13") -> Name | K18: =TR("T13") -> Name
C21: {=TR("T14")} -> Emergency Appeal 3
D22: =TR("T12") -> MDR code
D24: =TR("T13") -> Name
B27: =TR("T15") -> National Society key figures
B29: {=TR("T16")} -> Volunteers | C29: {=IFERROR(_xlfn._xlws.FILTER(UPR[ValueNum],(UPR[Country]=Data_Country)*(UPR[Indicator]="Number of people volunteering")),"")} | E29: {=TR("T17")} -> Staff | F29: {=IFERROR(_xlfn._xlws.FILTER(UPR[ValueNum],(UPR[Country]=Data_Country)*(UPR[Indicator]="Number of paid staff")),"")} | K29: {=TR("T18")} -> Local Units | L29: {=IFERROR(_xlfn._xlws.FILTER(UPR[ValueNum],(UPR[Country]=Data_Country)*(UPR[Indicator]="Number of National Society Local Units")),"")} | N29: {=TR("T19")} -> Branches | O29: {=IFERROR(_xlfn._xlws.FILTER(UPR[ValueNum],(UPR[Country]=Data_Country)*(UPR[Indicator]="Number of National Society branches")),"")}
B31: =IF(COUNTIFS(FDRS[Country],Data_Country,FDRS[Year],2024)=0,"","FDRS 2024 ->") | C31: {=IFERROR(_xlfn._xlws.FILTER(FDRS[Value],(FDRS[Country]=Data_Country)*(FDRS[Attribute]="Volunteers"))&"","")} | F31: {=IFERROR(_xlfn._xlws.FILTER(FDRS[Value],(FDRS[Country]=Data_Country)*(FDRS[Attribute]="Staff"))&" ","")} | L31: {=IFERROR(_xlfn._xlws.FILTER(FDRS[Value],(FDRS[Country]=Data_Country)*(FDRS[Attribute]="Local Units"))&" ","")} | O31: {=IFERROR(_xlfn._xlws.FILTER(FDRS[Value],(FDRS[Country]=Data_Country)*(FDRS[Attribute]="Branches"))&" ","")}
C33: {=TR("T39")} -> Figures for volunteers, staff, local units, and branches have been prefilled if the National Society has provided its data for 2025 unified annual reporting. Please review and update these numbers if needed. FDRS 2024 figures have been listed only for reference.
C35: {=TR("T18")} -> Local Units | I35: {=TR("T19")} -> Branches
C36: {=TR("T40")} -> ALL subdivisions of a National Society that coordinate and deliver services to people. These include ALL levels (provincial, state, city, district branches, sections or chapters, headquarters, regional and intermediate offices, as well as community-based units). | I36: {=TR("T41")} -> A Branch has its roles and responsibilities and relationship with the National Headquarters defined through National Societies’ Statutes, including the level of autonomy given, especially in its legal status, mobilizing local resources, building local partnerships, and decisions it makes. It has a local-level decision-making mechanism through its Branch members, board, and volunteers, equally defined through National Societies’ Statutes.

Sheet People to be reached
A1: {=IF(Data_Country="",TR("T42"),TR("T43")& IF(Language="EN", _xlfn.XLOOKUP(Data_Country, TemplateData!A2:A192, TemplateData!B2:B192), IF(Language="FR", _xlfn.XLOOKUP(Data_Country, TemplateData!A2:A192, TemplateData!C2:C192), IF(Language="SP", _xlfn.XLOOKUP(Data_Country, TemplateData!A2:A192, TemplateData!D2:D192), IF(Language="AR", _xlfn.XLOOKUP(Data_Country, TemplateData!A2:A192, TemplateData!E2:E192), "")))))} -> Please select your country at the Start page
B2: {=IFERROR( TR("T20") & " " & IF(Language="EN", _xlfn.XLOOKUP(Data_Country, TemplateData!A2:A192, TemplateData!B2:B192), IF(Language="FR", _xlfn.XLOOKUP(Data_Country, TemplateData!A2:A192, TemplateData!C2:C192), IF(Language="SP", _xlfn.XLOOKUP(Data_Country, TemplateData!A2:A192, TemplateData!D2:D192), IF(Language="AR", _xlfn.XLOOKUP(Data_Country, TemplateData!A2:A192, TemplateData!E2:E192), "")))), TR("T42") )} -> Please select your country at the Start page
C3: =TR("T21") -> Longer term programmes
C4: =TR("T22") -> Year | D4: {=TR(Data_People[[#Headers],[SP2]])} -> Response - Disasters and Crises | E4: {=TR(Data_People[[#Headers],[SP1]])} -> Resilience - Climate and Environment | F4: {=TR(Data_People[[#Headers],[SP3]])} -> Resilience - Health and Well-being | G4: {=TR(Data_People[[#Headers],[SP4]])} -> Resilience - Migration and Displacement | H4: {=TR(Data_People[[#Headers],[SP5]])} -> Respect - Values, Power and Inclusion
C5: Year | D5: SP2 | E5: SP1 | F5: SP3 | G5: SP4 | H5: SP5
C6: 2027 | J6: =IFERROR(VLOOKUP($B$6,'Planned Bilateral Support'!$C$5:$J$34,3,FALSE),"") | K6: =IFERROR(VLOOKUP($B$6,'Planned Bilateral Support'!$C$5:$J$34,4,FALSE),"") | L6: =IFERROR(VLOOKUP($B$6,'Planned Bilateral Support'!$C$5:$J$34,5,FALSE),"") | M6: =IFERROR(VLOOKUP($B$6,'Planned Bilateral Support'!$C$5:$J$34,6,FALSE),"") | N6: =IFERROR(VLOOKUP($B$6,'Planned Bilateral Support'!$C$5:$J$34,7,FALSE),"")
C7: 2028 | J7: =IFERROR(VLOOKUP($B$6,'Planned Bilateral Support'!$C$5:$J$34,3,FALSE),"") | K7: =IFERROR(VLOOKUP($B$6,'Planned Bilateral Support'!$C$5:$J$34,4,FALSE),"") | L7: =IFERROR(VLOOKUP($B$6,'Planned Bilateral Support'!$C$5:$J$34,5,FALSE),"") | M7: =IFERROR(VLOOKUP($B$6,'Planned Bilateral Support'!$C$5:$J$34,6,FALSE),"") | N7: =IFERROR(VLOOKUP($B$6,'Planned Bilateral Support'!$C$5:$J$34,7,FALSE),"")
C8: 2029 | J8: =IFERROR(VLOOKUP($B$6,'Planned Bilateral Support'!$C$5:$J$34,3,FALSE),"") | K8: =IFERROR(VLOOKUP($B$6,'Planned Bilateral Support'!$C$5:$J$34,4,FALSE),"") | L8: =IFERROR(VLOOKUP($B$6,'Planned Bilateral Support'!$C$5:$J$34,5,FALSE),"") | M8: =IFERROR(VLOOKUP($B$6,'Planned Bilateral Support'!$C$5:$J$34,6,FALSE),"") | N8: =IFERROR(VLOOKUP($B$6,'Planned Bilateral Support'!$C$5:$J$34,7,FALSE),"")
D10: =TR("T23") -> Emergency Appeals 2027
D11: =IF(OR(Data_MDR1 = "", Data_EA1 = ""), TR("T24"), Data_MDR1&" "&Data_EA1) -> Enter in the start page the name and MDR code for the Emergency Appeal
D12: =IF(OR(Data_MDR2 = "", Data_EA2 = ""), TR("T24"), Data_MDR2&" "&Data_EA2) -> Enter in the start page the name and MDR code for the Emergency Appeal
D13: =IF(OR(Data_MDR3 = "", Data_EA3 = ""), TR("T24"), Data_MDR3&" "&Data_EA3) -> Enter in the start page the name and MDR code for the Emergency Appeal

Sheet Planned Bilateral Support
A1: {=IF(Data_Country="",TR("T42"),TR("T43")& IF(Language="EN", _xlfn.XLOOKUP(Data_Country, TemplateData!A2:A192, TemplateData!B2:B192), IF(Language="FR", _xlfn.XLOOKUP(Data_Country, TemplateData!A2:A192, TemplateData!C2:C192), IF(Language="SP", _xlfn.XLOOKUP(Data_Country, TemplateData!A2:A192, TemplateData!D2:D192), IF(Language="AR", _xlfn.XLOOKUP(Data_Country, TemplateData!A2:A192, TemplateData!E2:E192), "")))))} -> Please select your country at the Start page
B2: =TR("T25") -> Planned Bilateral Support
B3: =TR("T08") -> Region | C3: =TR("T26") -> Participating National Society name | E3: {=TR(Data_Support[[#Headers],[SP2]])} -> Response - Disasters and Crises | F3: {=TR(Data_Support[[#Headers],[SP1]])} -> Resilience - Climate and Environment | G3: {=TR(Data_Support[[#Headers],[SP3]])} -> Resilience - Health and Well-being | H3: {=TR(Data_Support[[#Headers],[SP4]])} -> Resilience - Migration and Displacement | I3: {=TR(Data_Support[[#Headers],[SP5]])} -> Respect - Values, Power and Inclusion | J3: {=TR(Data_Support[[#Headers],[EFs]])} -> Enabling Functions
B4: Region | C4: National Society name | E4: SP2 | F4: SP1 | G4: SP3 | H4: SP4 | I4: SP5 | J4: EFs | K4: NS
K5: =IF(C5="","",_xlfn.XLOOKUP(C5,Table9[NS name],Table9[Value]))
K6: =IF(C6="","",_xlfn.XLOOKUP(C6,Table9[NS name],Table9[Value]))
K7: =IF(C7="","",_xlfn.XLOOKUP(C7,Table9[NS name],Table9[Value]))
K8: =IF(C8="","",_xlfn.XLOOKUP(C8,Table9[NS name],Table9[Value]))
K9: =IF(C9="","",_xlfn.XLOOKUP(C9,Table9[NS name],Table9[Value]))
K10: =IF(C10="","",_xlfn.XLOOKUP(C10,Table9[NS name],Table9[Value]))
K11: =IF(C11="","",_xlfn.XLOOKUP(C11,Table9[NS name],Table9[Value]))
K12: =IF(C12="","",_xlfn.XLOOKUP(C12,Table9[NS name],Table9[Value]))
K13: =IF(C13="","",_xlfn.XLOOKUP(C13,Table9[NS name],Table9[Value]))
K14: =IF(C14="","",_xlfn.XLOOKUP(C14,Table9[NS name],Table9[Value]))
K15: =IF(C15="","",_xlfn.XLOOKUP(C15,Table9[NS name],Table9[Value]))
K16: =IF(C16="","",_xlfn.XLOOKUP(C16,Table9[NS name],Table9[Value]))
... K34: =IF(C34="","",_xlfn.XLOOKUP(C34,Table9[NS name],Table9[Value]))

Sheet Funding requirements
A1: {=IF(Data_Country="",TR("T42"),TR("T43")& IF(Language="EN", _xlfn.XLOOKUP(Data_Country, TemplateData!A2:A192, TemplateData!B2:B192), IF(Language="FR", _xlfn.XLOOKUP(Data_Country, TemplateData!A2:A192, TemplateData!C2:C192), IF(Language="SP", _xlfn.XLOOKUP(Data_Country, TemplateData!A2:A192, TemplateData!D2:D192), IF(Language="AR", _xlfn.XLOOKUP(Data_Country, TemplateData!A2:A192, TemplateData!E2:E192), "")))))} -> Please select your country at the Start page
B2: =TR("T27") -> Funding requirements | J2: =TR("T27") -> Funding requirements | R2: =TR("T27") -> Funding requirements
B3: =TR("T28") -> If cell is grey, it means it's closed and you need to tick the relevant SP in the Activities page in order to open it. | K3: =TR("T28") -> If cell is grey, it means it's closed and you need to tick the relevant SP in the Activities page in order to open it.
F4: =TR("T29") -> All amounts in CHF | L4: =TR("T29") -> All amounts in CHF | R4: =TR("T29") -> All amounts in CHF
C5: =TR("T23") -> Emergency Appeals 2027 | F5: =TR("T30") -> 2027 Longer term programmes | L5: =TR("T31") -> 2028 Longer term programmes | R5: =TR("T32") -> 2029 Longer term programmes
B6: =TR("T33") -> IFRC network member | C6: =IF(OR(Data_MDR1 = "", Data_EA1 = ""), TR("T24"), Data_MDR1&" "&Data_EA1) -> Enter in the start page the name and MDR code for the Emergency Appeal | D6: =IF(OR(Data_MDR2 = "", Data_EA2 = ""), TR("T24"), Data_MDR2&" "&Data_EA2) -> Enter in the start page the name and MDR code for the Emergency Appeal | E6: =IF(OR(Data_MDR3 = "", Data_EA3 = ""), TR("T24"), Data_MDR3&" "&Data_EA3) -> Enter in the start page the name and MDR code for the Emergency Appeal | F6: {=TR(LEFT(Data_FR[[#Headers],[SP2_2027]],3))} -> Response - Disasters and Crises | G6: {=TR(LEFT(Data_FR[[#Headers],[SP1_2027]],3))} -> Resilience - Climate and Environment | H6: {=TR(LEFT(Data_FR[[#Headers],[SP3_2027]],3))} -> Resilience - Health and Well-being | I6: {=TR(LEFT(Data_FR[[#Headers],[SP4_2027]],3))} -> Resilience - Migration and Displacement | J6: {=TR(LEFT(Data_FR[[#Headers],[SP5_2027]],3))} -> Respect - Values, Power and Inclusion | K6: {=TR(LEFT(Data_FR[[#Headers],[EFs_2027]],3))} -> Enabling Functions | L6: {=TR(LEFT(Data_FR[[#Headers],[SP2_2028]],3))} -> Response - Disasters and Crises | M6: {=TR(LEFT(Data_FR[[#Headers],[SP1_2028]],3))} -> Resilience - Climate and Environment | N6: {=TR(LEFT(Data_FR[[#Headers],[SP3_2028]],3))} -> Resilience - Health and Well-being | O6: {=TR(LEFT(Data_FR[[#Headers],[SP4_2028]],3))} -> Resilience - Migration and Displacement | P6: {=TR(LEFT(Data_FR[[#Headers],[SP5_2028]],3))} -> Respect - Values, Power and Inclusion | Q6: {=TR(LEFT(Data_FR[[#Headers],[EFs_2028]],3))} -> Enabling Functions | R6: {=TR(LEFT(Data_FR[[#Headers],[SP2_2029]],3))} -> Response - Disasters and Crises | S6: {=TR(LEFT(Data_FR[[#Headers],[SP1_2029]],3))} -> Resilience - Climate and Environment | T6: {=TR(LEFT(Data_FR[[#Headers],[SP3_2029]],3))} -> Resilience - Health and Well-being | U6: {=TR(LEFT(Data_FR[[#Headers],[SP4_2029]],3))} -> Resilience - Migration and Displacement | V6: {=TR(LEFT(Data_FR[[#Headers],[SP5_2029]],3))} -> Respect - Values, Power and Inclusion | W6: {=TR(LEFT(Data_FR[[#Headers],[EFs_2029]],3))} -> Enabling Functions
B7: National Society name | C7: EA1_2027 | D7: EA2_2027 | E7: EA3_2027 | F7: SP2_2027 | G7: SP1_2027 | H7: SP3_2027 | I7: SP4_2027 | J7: SP5_2027 | K7: EFs_2027 | L7: SP2_2028 | M7: SP1_2028 | N7: SP3_2028 | O7: SP4_2028 | P7: SP5_2028 | Q7: EFs_2028 | R7: SP2_2029 | S7: SP1_2029 | T7: SP3_2029 | U7: SP4_2029 | V7: SP5_2029 | W7: EFs_2029 | X7: NS | Z7: SP1 | AA7: SP2 | AB7: Sp3 | AC7: SP4 | AD7: SP5 | AE7: EA
B8: =IFERROR( TR("T34") & _xlfn.UNICHAR(10) & IF(Language="EN", _xlfn.XLOOKUP(Data_Country, TemplateData!A2:A192, TemplateData!B2:B192), IF(Language="SP", _xlfn.XLOOKUP(Data_Country, TemplateData!A2:A192, TemplateData!C2:C192), IF(Language="FR", _xlfn.XLOOKUP(Data_Country, TemplateData!A2:A192, TemplateData!D2:D192), IF(Language="AR", _xlfn.XLOOKUP(Data_Country, TemplateData!A2:A192, TemplateData!E2:E192), "")))), "Select a country in the Start page" ) -> Select a country in the Start page | X8: ="Host National Society"&_xlfn.UNICHAR(10)&_xlfn.XLOOKUP(Data_Country,TemplateData!A2:A192,TemplateData!B2:B192) -> #N/A
B9: =TR("T35") -> IFRC Secretariat | X9: IFRC Secretariat
B10: {=IFERROR(_xlfn.UNIQUE(_xlfn._xlws.FILTER('Planned Bilateral Support'!$C$5:$C$34,'Planned Bilateral Support'!$C$5:$C$34<>"")),"")} | X10: =IF(B10="","",_xlfn.XLOOKUP(B10,Table9[NS name],Table9[Value])) | Z10: =IFERROR(_xlfn.XLOOKUP($X10,Data_Support[NS],Data_Support[SP2]),"") -> 0 | AA10: =IFERROR(_xlfn.XLOOKUP($X10,Data_Support[NS],Data_Support[SP1]),"") -> 0 | AB10: =IFERROR(_xlfn.XLOOKUP($X10,Data_Support[NS],Data_Support[SP3]),"") -> 0 | AC10: =IFERROR(_xlfn.XLOOKUP($X10,Data_Support[NS],Data_Support[SP4]),"") -> 0 | AD10: =IFERROR(_xlfn.XLOOKUP($X10,Data_Support[NS],Data_Support[SP5]),"") -> 0 | AE10: =IFERROR(_xlfn.XLOOKUP($X10,Data_Support[NS],Data_Support[EFs]),"") -> 0
X11: =IF(B11="","",_xlfn.XLOOKUP(B11,Table9[NS name],Table9[Value])) | Z11: =IFERROR(_xlfn.XLOOKUP($X11,Data_Support[NS],Data_Support[SP2]),"") -> 0 | AA11: =IFERROR(_xlfn.XLOOKUP($X11,Data_Support[NS],Data_Support[SP1]),"") -> 0 | AB11: =IFERROR(_xlfn.XLOOKUP($X11,Data_Support[NS],Data_Support[SP3]),"") -> 0 | AC11: =IFERROR(_xlfn.XLOOKUP($X11,Data_Support[NS],Data_Support[SP4]),"") -> 0 | AD11: =IFERROR(_xlfn.XLOOKUP($X11,Data_Support[NS],Data_Support[SP5]),"") -> 0 | AE11: =IFERROR(_xlfn.XLOOKUP($X11,Data_Support[NS],Data_Support[EFs]),"") -> 0
X12: =IF(B12="","",_xlfn.XLOOKUP(B12,Table9[NS name],Table9[Value])) | Z12: =IFERROR(_xlfn.XLOOKUP($X12,Data_Support[NS],Data_Support[SP2]),"") -> 0 | AA12: =IFERROR(_xlfn.XLOOKUP($X12,Data_Support[NS],Data_Support[SP1]),"") -> 0 | AB12: =IFERROR(_xlfn.XLOOKUP($X12,Data_Support[NS],Data_Support[SP3]),"") -> 0 | AC12: =IFERROR(_xlfn.XLOOKUP($X12,Data_Support[NS],Data_Support[SP4]),"") -> 0 | AD12: =IFERROR(_xlfn.XLOOKUP($X12,Data_Support[NS],Data_Support[SP5]),"") -> 0 | AE12: =IFERROR(_xlfn.XLOOKUP($X12,Data_Support[NS],Data_Support[EFs]),"") -> 0
X13: =IF(B13="","",_xlfn.XLOOKUP(B13,Table9[NS name],Table9[Value])) | Z13: =IFERROR(_xlfn.XLOOKUP($X13,Data_Support[NS],Data_Support[SP2]),"") -> 0 | AA13: =IFERROR(_xlfn.XLOOKUP($X13,Data_Support[NS],Data_Support[SP1]),"") -> 0 | AB13: =IFERROR(_xlfn.XLOOKUP($X13,Data_Support[NS],Data_Support[SP3]),"") -> 0 | AC13: =IFERROR(_xlfn.XLOOKUP($X13,Data_Support[NS],Data_Support[SP4]),"") -> 0 | AD13: =IFERROR(_xlfn.XLOOKUP($X13,Data_Support[NS],Data_Support[SP5]),"") -> 0 | AE13: =IFERROR(_xlfn.XLOOKUP($X13,Data_Support[NS],Data_Support[EFs]),"") -> 0
X14: =IF(B14="","",_xlfn.XLOOKUP(B14,Table9[NS name],Table9[Value])) | Z14: =IFERROR(_xlfn.XLOOKUP($X14,Data_Support[NS],Data_Support[SP2]),"") -> 0 | AA14: =IFERROR(_xlfn.XLOOKUP($X14,Data_Support[NS],Data_Support[SP1]),"") -> 0 | AB14: =IFERROR(_xlfn.XLOOKUP($X14,Data_Support[NS],Data_Support[SP3]),"") -> 0 | AC14: =IFERROR(_xlfn.XLOOKUP($X14,Data_Support[NS],Data_Support[SP4]),"") -> 0 | AD14: =IFERROR(_xlfn.XLOOKUP($X14,Data_Support[NS],Data_Support[SP5]),"") -> 0 | AE14: =IFERROR(_xlfn.XLOOKUP($X14,Data_Support[NS],Data_Support[EFs]),"") -> 0
X15: =IF(B15="","",_xlfn.XLOOKUP(B15,Table9[NS name],Table9[Value])) | Z15: =IFERROR(_xlfn.XLOOKUP($X15,Data_Support[NS],Data_Support[SP2]),"") -> 0 | AA15: =IFERROR(_xlfn.XLOOKUP($X15,Data_Support[NS],Data_Support[SP1]),"") -> 0 | AB15: =IFERROR(_xlfn.XLOOKUP($X15,Data_Support[NS],Data_Support[SP3]),"") -> 0 | AC15: =IFERROR(_xlfn.XLOOKUP($X15,Data_Support[NS],Data_Support[SP4]),"") -> 0 | AD15: =IFERROR(_xlfn.XLOOKUP($X15,Data_Support[NS],Data_Support[SP5]),"") -> 0 | AE15: =IFERROR(_xlfn.XLOOKUP($X15,Data_Support[NS],Data_Support[EFs]),"") -> 0
X16: =IF(B16="","",_xlfn.XLOOKUP(B16,Table9[NS name],Table9[Value])) | Z16: =IFERROR(_xlfn.XLOOKUP($X16,Data_Support[NS],Data_Support[SP2]),"") -> 0 | AA16: =IFERROR(_xlfn.XLOOKUP($X16,Data_Support[NS],Data_Support[SP1]),"") -> 0 | AB16: =IFERROR(_xlfn.XLOOKUP($X16,Data_Support[NS],Data_Support[SP3]),"") -> 0 | AC16: =IFERROR(_xlfn.XLOOKUP($X16,Data_Support[NS],Data_Support[SP4]),"") -> 0 | AD16: =IFERROR(_xlfn.XLOOKUP($X16,Data_Support[NS],Data_Support[SP5]),"") -> 0 | AE16: =IFERROR(_xlfn.XLOOKUP($X16,Data_Support[NS],Data_Support[EFs]),"") -> 0
X17: =IF(B17="","",_xlfn.XLOOKUP(B17,Table9[NS name],Table9[Value])) | Z17: =IFERROR(_xlfn.XLOOKUP($X17,Data_Support[NS],Data_Support[SP2]),"") -> 0 | AA17: =IFERROR(_xlfn.XLOOKUP($X17,Data_Support[NS],Data_Support[SP1]),"") -> 0 | AB17: =IFERROR(_xlfn.XLOOKUP($X17,Data_Support[NS],Data_Support[SP3]),"") -> 0 | AC17: =IFERROR(_xlfn.XLOOKUP($X17,Data_Support[NS],Data_Support[SP4]),"") -> 0 | AD17: =IFERROR(_xlfn.XLOOKUP($X17,Data_Support[NS],Data_Support[SP5]),"") -> 0 | AE17: =IFERROR(_xlfn.XLOOKUP($X17,Data_Support[NS],Data_Support[EFs]),"") -> 0
X18: =IF(B18="","",_xlfn.XLOOKUP(B18,Table9[NS name],Table9[Value])) | Z18: =IFERROR(_xlfn.XLOOKUP($X18,Data_Support[NS],Data_Support[SP2]),"") -> 0 | AA18: =IFERROR(_xlfn.XLOOKUP($X18,Data_Support[NS],Data_Support[SP1]),"") -> 0 | AB18: =IFERROR(_xlfn.XLOOKUP($X18,Data_Support[NS],Data_Support[SP3]),"") -> 0 | AC18: =IFERROR(_xlfn.XLOOKUP($X18,Data_Support[NS],Data_Support[SP4]),"") -> 0 | AD18: =IFERROR(_xlfn.XLOOKUP($X18,Data_Support[NS],Data_Support[SP5]),"") -> 0 | AE18: =IFERROR(_xlfn.XLOOKUP($X18,Data_Support[NS],Data_Support[EFs]),"") -> 0
X19: =IF(B19="","",_xlfn.XLOOKUP(B19,Table9[NS name],Table9[Value])) | Z19: =IFERROR(_xlfn.XLOOKUP($X19,Data_Support[NS],Data_Support[SP2]),"") -> 0 | AA19: =IFERROR(_xlfn.XLOOKUP($X19,Data_Support[NS],Data_Support[SP1]),"") -> 0 | AB19: =IFERROR(_xlfn.XLOOKUP($X19,Data_Support[NS],Data_Support[SP3]),"") -> 0 | AC19: =IFERROR(_xlfn.XLOOKUP($X19,Data_Support[NS],Data_Support[SP4]),"") -> 0 | AD19: =IFERROR(_xlfn.XLOOKUP($X19,Data_Support[NS],Data_Support[SP5]),"") -> 0 | AE19: =IFERROR(_xlfn.XLOOKUP($X19,Data_Support[NS],Data_Support[EFs]),"") -> 0
X20: =IF(B20="","",_xlfn.XLOOKUP(B20,Table9[NS name],Table9[Value])) | Z20: =IFERROR(_xlfn.XLOOKUP($X20,Data_Support[NS],Data_Support[SP2]),"") -> 0 | AA20: =IFERROR(_xlfn.XLOOKUP($X20,Data_Support[NS],Data_Support[SP1]),"") -> 0 | AB20: =IFERROR(_xlfn.XLOOKUP($X20,Data_Support[NS],Data_Support[SP3]),"") -> 0 | AC20: =IFERROR(_xlfn.XLOOKUP($X20,Data_Support[NS],Data_Support[SP4]),"") -> 0 | AD20: =IFERROR(_xlfn.XLOOKUP($X20,Data_Support[NS],Data_Support[SP5]),"") -> 0 | AE20: =IFERROR(_xlfn.XLOOKUP($X20,Data_Support[NS],Data_Support[EFs]),"") -> 0
X21: =IF(B21="","",_xlfn.XLOOKUP(B21,Table9[NS name],Table9[Value])) | Z21: =IFERROR(_xlfn.XLOOKUP($X21,Data_Support[NS],Data_Support[SP2]),"") -> 0 | AA21: =IFERROR(_xlfn.XLOOKUP($X21,Data_Support[NS],Data_Support[SP1]),"") -> 0 | AB21: =IFERROR(_xlfn.XLOOKUP($X21,Data_Support[NS],Data_Support[SP3]),"") -> 0 | AC21: =IFERROR(_xlfn.XLOOKUP($X21,Data_Support[NS],Data_Support[SP4]),"") -> 0 | AD21: =IFERROR(_xlfn.XLOOKUP($X21,Data_Support[NS],Data_Support[SP5]),"") -> 0 | AE21: =IFERROR(_xlfn.XLOOKUP($X21,Data_Support[NS],Data_Support[EFs]),"") -> 0
X22: =IF(B22="","",_xlfn.XLOOKUP(B22,Table9[NS name],Table9[Value])) | Z22: =IFERROR(_xlfn.XLOOKUP($X22,Data_Support[NS],Data_Support[SP2]),"") -> 0 | AA22: =IFERROR(_xlfn.XLOOKUP($X22,Data_Support[NS],Data_Support[SP1]),"") -> 0 | AB22: =IFERROR(_xlfn.XLOOKUP($X22,Data_Support[NS],Data_Support[SP3]),"") -> 0 | AC22: =IFERROR(_xlfn.XLOOKUP($X22,Data_Support[NS],Data_Support[SP4]),"") -> 0 | AD22: =IFERROR(_xlfn.XLOOKUP($X22,Data_Support[NS],Data_Support[SP5]),"") -> 0 | AE22: =IFERROR(_xlfn.XLOOKUP($X22,Data_Support[NS],Data_Support[EFs]),"") -> 0
... X33: =IF(B33="","",_xlfn.XLOOKUP(B33,Table9[NS name],Table9[Value])) | Z33: =IFERROR(_xlfn.XLOOKUP($X33,Data_Support[NS],Data_Support[SP2]),"") -> 0 | AA33: =IFERROR(_xlfn.XLOOKUP($X33,Data_Support[NS],Data_Support[SP1]),"") -> 0 | AB33: =IFERROR(_xlfn.XLOOKUP($X33,Data_Support[NS],Data_Support[SP3]),"") -> 0 | AC33: =IFERROR(_xlfn.XLOOKUP($X33,Data_Support[NS],Data_Support[SP4]),"") -> 0 | AD33: =IFERROR(_xlfn.XLOOKUP($X33,Data_Support[NS],Data_Support[SP5]),"") -> 0 | AE33: =IFERROR(_xlfn.XLOOKUP($X33,Data_Support[NS],Data_Support[EFs]),"") -> 0

Sheet Comments
G2: =TR("T36") -> Comments
